Traceback (most recent call last):
  File "C:\Users\Alaa\.conda\envs\uoft\lib\site-packages\jupyter_cache\executors\utils.py", line 58, in single_nb_execution
    executenb(
  File "C:\Users\Alaa\.conda\envs\uoft\lib\site-packages\nbclient\client.py", line 1269, in execute
    return NotebookClient(nb=nb, resources=resources, km=km, **kwargs).execute()
  File "C:\Users\Alaa\.conda\envs\uoft\lib\site-packages\nbclient\util.py", line 85, in wrapped
    return just_run(coro(*args, **kwargs))
  File "C:\Users\Alaa\.conda\envs\uoft\lib\site-packages\nbclient\util.py", line 60, in just_run
    return loop.run_until_complete(coro)
  File "C:\Users\Alaa\.conda\envs\uoft\lib\asyncio\base_events.py", line 646, in run_until_complete
    return future.result()
  File "C:\Users\Alaa\.conda\envs\uoft\lib\site-packages\nbclient\client.py", line 707, in async_execute
    await self.async_execute_cell(
  File "C:\Users\Alaa\.conda\envs\uoft\lib\site-packages\nbclient\client.py", line 1025, in async_execute_cell
    await self._check_raise_for_error(cell, cell_index, exec_reply)
  File "C:\Users\Alaa\.conda\envs\uoft\lib\site-packages\nbclient\client.py", line 919, in _check_raise_for_error
    raise CellExecutionError.from_cell_and_msg(cell, exec_reply_content)
nbclient.exceptions.CellExecutionError: An error occurred while executing the following cell:
------------------
import osmnx
import pandas as pd
from smart_mobility_utilities.common import Node
from collections import *
from collections import *
import numpy as np
from pymoo.core.problem import Problem
import random
from smart_mobility_utilities.common import cost
import numpy as np
from pymoo.core.duplicate import ElementwiseDuplicateElimination
from pymoo.core.mutation import Mutation
from pymoo.core.sampling import Sampling
from pymoo.core.crossover import Crossover
from pymoo.algorithms.moo.nsga2 import NSGA2
from pymoo.optimize import minimize
from matplotlib import pyplot as plt
import osmnx
import pandas as pd
import matplotlib.pyplot as plt
from smart_mobility_utilities.common import Node
from smart_mobility_utilities.viz import draw_route
from smart_mobility_utilities.viz import draw_map
from smart_mobility_utilities.common import randomized_search, cost, probability
from smart_mobility_utilities.children import get_children
from tqdm.notebook import tqdm
import random
import tabulate
import itertools
import timeit
------------------

[1;31m---------------------------------------------------------------------------[0m
[1;31mModuleNotFoundError[0m                       Traceback (most recent call last)
Input [1;32mIn [1][0m, in [0;36m<cell line: 3>[1;34m()[0m
[0;32m      1[0m [38;5;28;01mimport[39;00m [38;5;21;01mosmnx[39;00m
[0;32m      2[0m [38;5;28;01mimport[39;00m [38;5;21;01mpandas[39;00m [38;5;28;01mas[39;00m [38;5;21;01mpd[39;00m
[1;32m----> 3[0m [38;5;28;01mfrom[39;00m [38;5;21;01msmart_mobility_utilities[39;00m[38;5;21;01m.[39;00m[38;5;21;01mcommon[39;00m [38;5;28;01mimport[39;00m Node
[0;32m      4[0m [38;5;28;01mfrom[39;00m [38;5;21;01mcollections[39;00m [38;5;28;01mimport[39;00m [38;5;241m*[39m
[0;32m      5[0m [38;5;28;01mfrom[39;00m [38;5;21;01mcollections[39;00m [38;5;28;01mimport[39;00m [38;5;241m*[39m

[1;31mModuleNotFoundError[0m: No module named 'smart_mobility_utilities'
ModuleNotFoundError: No module named 'smart_mobility_utilities'

